Workbook
Name EarlyYears_Subjects: Lists!$E$2:$E$50
Name LowerPrimary_Subjects: Lists!$F$2:$F$50
Name UpperPrimary_Subjects: Lists!$H$2:$H$50
Name JuniorSchool_Subjects: Lists!$I$2:$I$80

Sheet Classes
A1: Campus | B1: Academic Group | C1: Level | D1: Stream | E1: Class Name
A2: Upper | B2: Early Years | C2: Foundation | D2: Love | E2: Foundation – Love
A3: Upper | B3: Early Years | C3: Foundation | D3: Peace | E3: Foundation – Peace
A4: Upper | B4: Early Years | C4: PP1 | D4: Love | E4: PP1 – Love
A5: Upper | B5: Early Years | C5: PP1 | D5: Peace | E5: PP1 – Peace
A6: Upper | B6: Early Years | C6: PP2 | D6: Love | E6: PP2 – Love
A7: Upper | B7: Early Years | C7: PP2 | D7: Peace | E7: PP2 – Peace
A8: Upper | B8: Lower Primary | C8: Grade 1 | D8: Love | E8: Grade 1 – Love
A9: Upper | B9: Lower Primary | C9: Grade 1 | D9: Peace | E9: Grade 1 – Peace
A10: Upper | B10: Lower Primary | C10: Grade 2 | D10: Love | E10: Grade 2 – Love
A11: Upper | B11: Lower Primary | C11: Grade 2 | D11: Peace | E11: Grade 2 – Peace
A12: Lower | B12: Upper Primary | C12: Grade 4 | D12: A | E12: Grade 4 – A
... A23: Lower | B23: Junior School | C23: Grade 9 | D23: B | E23: Grade 9 – B

Sheet Teacher Allocation
A1: SUBJECT TEACHER ALLOCATION (LOWER CAMPUS – UPPER PRIMARY & JUNIOR SCHOOL)
A2: Campus | B2: Section | C2: Class | D2: Subject | E2: Teacher Name | F2: Role | G2: Week Start | H2: Week End | I2: Notes
F3: Subject Teacher
F4: Subject Teacher
F5: Subject Teacher
F6: Subject Teacher
F7: Subject Teacher
F8: Subject Teacher
F9: Subject Teacher
F10: Subject Teacher
F11: Subject Teacher
F12: Subject Teacher
F13: Subject Teacher
F14: Subject Teacher
... F302: Subject Teacher

Sheet Lower Campus Dashboard
A1: ROYAL KINGS PREMIER SCHOOL
A2: LOWER CAMPUS DASHBOARD (UPPER PRIMARY & JUNIOR SCHOOL)
A4: Week Ending (optional):
A6: SECTION PERFORMANCE (AVERAGE %)
A7: Section | B7: Average % | C7: Status
A8: Upper Primary | B8: =IF($B$4="",ROUND(AVERAGEIFS(Assessments!$J:$J,Assessments!$C:$C,"Lower",Assessments!$K:$K,"Upper Primary"),0),ROUND(AVERAGEIFS(Assessments!$J:$J,Assessments!$C:$C,"Lower",Assessments!$K:$K,"Upper Primary",Assessments!$B:$B,$B$4),0)) | C8: =IF(B8="","",IF(B8>=70,"🟢",IF(B8>=50,"🟠","🔴")))
A9: Junior School | B9: =IF($B$4="",ROUND(AVERAGEIFS(Assessments!$J:$J,Assessments!$C:$C,"Lower",Assessments!$K:$K,"Junior School"),0),ROUND(AVERAGEIFS(Assessments!$J:$J,Assessments!$C:$C,"Lower",Assessments!$K:$K,"Junior School",Assessments!$B:$B,$B$4),0)) | C9: =IF(B9="","",IF(B9>=70,"🟢",IF(B9>=50,"🟠","🔴")))

Sheet Lower Campus Heatmap
A1: ROYAL KINGS PREMIER SCHOOL
A2: LOWER CAMPUS HEATMAP TEMPLATE (GRADE 4–9)
A4: Auto-colors class averages by subject once Assessments data includes Grade 4–9 classes & subjects.
A6: Section | B6: Class | C6: English | D6: Kiswahili | E6: Mathematics | F6: Science | G6: Integrated Science | H6: Social Studies | I6: CRE | J6: Computer Studies | K6: Class Avg %
A7: Upper Primary | B7: Grade 4 – A | C7: =IFERROR(ROUND(AVERAGEIFS(Assessments!$J:$J,Assessments!$C:$C,"Lower",Assessments!$K:$K,"Upper Primary",Assessments!$D:$D,"Grade 4 – A",Assessments!$E:$E,"English"),0),"") | D7: =IFERROR(ROUND(AVERAGEIFS(Assessments!$J:$J,Assessments!$C:$C,"Lower",Assessments!$K:$K,"Upper Primary",Assessments!$D:$D,"Grade 4 – A",Assessments!$E:$E,"Kiswahili"),0),"") | E7: =IFERROR(ROUND(AVERAGEIFS(Assessments!$J:$J,Assessments!$C:$C,"Lower",Assessments!$K:$K,"Upper Primary",Assessments!$D:$D,"Grade 4 – A",Assessments!$E:$E,"Mathematics"),0),"") | F7: =IFERROR(ROUND(AVERAGEIFS(Assessments!$J:$J,Assessments!$C:$C,"Lower",Assessments!$K:$K,"Upper Primary",Assessments!$D:$D,"Grade 4 – A",Assessments!$E:$E,"Science"),0),"") | G7: =IFERROR(ROUND(AVERAGEIFS(Assessments!$J:$J,Assessments!$C:$C,"Lower",Assessments!$K:$K,"Upper Primary",Assessments!$D:$D,"Grade 4 – A",Assessments!$E:$E,"Integrated Science"),0),"") | H7: =IFERROR(ROUND(AVERAGEIFS(Assessments!$J:$J,Assessments!$C:$C,"Lower",Assessments!$K:$K,"Upper Primary",Assessments!$D:$D,"Grade 4 – A",Assessments!$E:$E,"Social Studies"),0),"") | I7: =IFERROR(ROUND(AVERAGEIFS(Assessments!$J:$J,Assessments!$C:$C,"Lower",Assessments!$K:$K,"Upper Primary",Assessments!$D:$D,"Grade 4 – A",Assessments!$E:$E,"CRE"),0),"") | J7: =IFERROR(ROUND(AVERAGEIFS(Assessments!$J:$J,Assessments!$C:$C,"Lower",Assessments!$K:$K,"Upper Primary",Assessments!$D:$D,"Grade 4 – A",Assessments!$E:$E,"Computer Studies"),0),"") | K7: =IFERROR(ROUND(AVERAGEIFS(Assessments!$J:$J,Assessments!$C:$C,"Lower",Assessments!$K:$K,"Upper Primary",Assessments!$D:$D,"Grade 4 – A"),0),"")
A8: Upper Primary | B8: Grade 4 – B | C8: =IFERROR(ROUND(AVERAGEIFS(Assessments!$J:$J,Assessments!$C:$C,"Lower",Assessments!$K:$K,"Upper Primary",Assessments!$D:$D,"Grade 4 – B",Assessments!$E:$E,"English"),0),"") | D8: =IFERROR(ROUND(AVERAGEIFS(Assessments!$J:$J,Assessments!$C:$C,"Lower",Assessments!$K:$K,"Upper Primary",Assessments!$D:$D,"Grade 4 – B",Assessments!$E:$E,"Kiswahili"),0),"") | E8: =IFERROR(ROUND(AVERAGEIFS(Assessments!$J:$J,Assessments!$C:$C,"Lower",Assessments!$K:$K,"Upper Primary",Assessments!$D:$D,"Grade 4 – B",Assessments!$E:$E,"Mathematics"),0),"") | F8: =IFERROR(ROUND(AVERAGEIFS(Assessments!$J:$J,Assessments!$C:$C,"Lower",Assessments!$K:$K,"Upper Primary",Assessments!$D:$D,"Grade 4 – B",Assessments!$E:$E,"Science"),0),"") | G8: =IFERROR(ROUND(AVERAGEIFS(Assessments!$J:$J,Assessments!$C:$C,"Lower",Assessments!$K:$K,"Upper Primary",Assessments!$D:$D,"Grade 4 – B",Assessments!$E:$E,"Integrated Science"),0),"") | H8: =IFERROR(ROUND(AVERAGEIFS(Assessments!$J:$J,Assessments!$C:$C,"Lower",Assessments!$K:$K,"Upper Primary",Assessments!$D:$D,"Grade 4 – B",Assessments!$E:$E,"Social Studies"),0),"") | I8: =IFERROR(ROUND(AVERAGEIFS(Assessments!$J:$J,Assessments!$C:$C,"Lower",Assessments!$K:$K,"Upper Primary",Assessments!$D:$D,"Grade 4 – B",Assessments!$E:$E,"CRE"),0),"") | J8: =IFERROR(ROUND(AVERAGEIFS(Assessments!$J:$J,Assessments!$C:$C,"Lower",Assessments!$K:$K,"Upper Primary",Assessments!$D:$D,"Grade 4 – B",Assessments!$E:$E,"Computer Studies"),0),"") | K8: =IFERROR(ROUND(AVERAGEIFS(Assessments!$J:$J,Assessments!$C:$C,"Lower",Assessments!$K:$K,"Upper Primary",Assessments!$D:$D,"Grade 4 – B"),0),"")
A9: Upper Primary | B9: Grade 5 – A | C9: =IFERROR(ROUND(AVERAGEIFS(Assessments!$J:$J,Assessments!$C:$C,"Lower",Assessments!$K:$K,"Upper Primary",Assessments!$D:$D,"Grade 5 – A",Assessments!$E:$E,"English"),0),"") | D9: =IFERROR(ROUND(AVERAGEIFS(Assessments!$J:$J,Assessments!$C:$C,"Lower",Assessments!$K:$K,"Upper Primary",Assessments!$D:$D,"Grade 5 – A",Assessments!$E:$E,"Kiswahili"),0),"") | E9: =IFERROR(ROUND(AVERAGEIFS(Assessments!$J:$J,Assessments!$C:$C,"Lower",Assessments!$K:$K,"Upper Primary",Assessments!$D:$D,"Grade 5 – A",Assessments!$E:$E,"Mathematics"),0),"") | F9: =IFERROR(ROUND(AVERAGEIFS(Assessments!$J:$J,Assessments!$C:$C,"Lower",Assessments!$K:$K,"Upper Primary",Assessments!$D:$D,"Grade 5 – A",Assessments!$E:$E,"Science"),0),"") | G9: =IFERROR(ROUND(AVERAGEIFS(Assessments!$J:$J,Assessments!$C:$C,"Lower",Assessments!$K:$K,"Upper Primary",Assessments!$D:$D,"Grade 5 – A",Assessments!$E:$E,"Integrated Science"),0),"") | H9: =IFERROR(ROUND(AVERAGEIFS(Assessments!$J:$J,Assessments!$C:$C,"Lower",Assessments!$K:$K,"Upper Primary",Assessments!$D:$D,"Grade 5 – A",Assessments!$E:$E,"Social Studies"),0),"") | I9: =IFERROR(ROUND(AVERAGEIFS(Assessments!$J:$J,Assessments!$C:$C,"Lower",Assessments!$K:$K,"Upper Primary",Assessments!$D:$D,"Grade 5 – A",Assessments!$E:$E,"CRE"),0),"") | J9: =IFERROR(ROUND(AVERAGEIFS(Assessments!$J:$J,Assessments!$C:$C,"Lower",Assessments!$K:$K,"Upper Primary",Assessments!$D:$D,"Grade 5 – A",Assessments!$E:$E,"Computer Studies"),0),"") | K9: =IFERROR(ROUND(AVERAGEIFS(Assessments!$J:$J,Assessments!$C:$C,"Lower",Assessments!$K:$K,"Upper Primary",Assessments!$D:$D,"Grade 5 – A"),0),"")
A10: Upper Primary | B10: Grade 5 – B | C10: =IFERROR(ROUND(AVERAGEIFS(Assessments!$J:$J,Assessments!$C:$C,"Lower",Assessments!$K:$K,"Upper Primary",Assessments!$D:$D,"Grade 5 – B",Assessments!$E:$E,"English"),0),"") | D10: =IFERROR(ROUND(AVERAGEIFS(Assessments!$J:$J,Assessments!$C:$C,"Lower",Assessments!$K:$K,"Upper Primary",Assessments!$D:$D,"Grade 5 – B",Assessments!$E:$E,"Kiswahili"),0),"") | E10: =IFERROR(ROUND(AVERAGEIFS(Assessments!$J:$J,Assessments!$C:$C,"Lower",Assessments!$K:$K,"Upper Primary",Assessments!$D:$D,"Grade 5 – B",Assessments!$E:$E,"Mathematics"),0),"") | F10: =IFERROR(ROUND(AVERAGEIFS(Assessments!$J:$J,Assessments!$C:$C,"Lower",Assessments!$K:$K,"Upper Primary",Assessments!$D:$D,"Grade 5 – B",Assessments!$E:$E,"Science"),0),"") | G10: =IFERROR(ROUND(AVERAGEIFS(Assessments!$J:$J,Assessments!$C:$C,"Lower",Assessments!$K:$K,"Upper Primary",Assessments!$D:$D,"Grade 5 – B",Assessments!$E:$E,"Integrated Science"),0),"") | H10: =IFERROR(ROUND(AVERAGEIFS(Assessments!$J:$J,Assessments!$C:$C,"Lower",Assessments!$K:$K,"Upper Primary",Assessments!$D:$D,"Grade 5 – B",Assessments!$E:$E,"Social Studies"),0),"") | I10: =IFERROR(ROUND(AVERAGEIFS(Assessments!$J:$J,Assessments!$C:$C,"Lower",Assessments!$K:$K,"Upper Primary",Assessments!$D:$D,"Grade 5 – B",Assessments!$E:$E,"CRE"),0),"") | J10: =IFERROR(ROUND(AVERAGEIFS(Assessments!$J:$J,Assessments!$C:$C,"Lower",Assessments!$K:$K,"Upper Primary",Assessments!$D:$D,"Grade 5 – B",Assessments!$E:$E,"Computer Studies"),0),"") | K10: =IFERROR(ROUND(AVERAGEIFS(Assessments!$J:$J,Assessments!$C:$C,"Lower",Assessments!$K:$K,"Upper Primary",Assessments!$D:$D,"Grade 5 – B"),0),"")
A11: Upper Primary | B11: Grade 6 – A | C11: =IFERROR(ROUND(AVERAGEIFS(Assessments!$J:$J,Assessments!$C:$C,"Lower",Assessments!$K:$K,"Upper Primary",Assessments!$D:$D,"Grade 6 – A",Assessments!$E:$E,"English"),0),"") | D11: =IFERROR(ROUND(AVERAGEIFS(Assessments!$J:$J,Assessments!$C:$C,"Lower",Assessments!$K:$K,"Upper Primary",Assessments!$D:$D,"Grade 6 – A",Assessments!$E:$E,"Kiswahili"),0),"") | E11: =IFERROR(ROUND(AVERAGEIFS(Assessments!$J:$J,Assessments!$C:$C,"Lower",Assessments!$K:$K,"Upper Primary",Assessments!$D:$D,"Grade 6 – A",Assessments!$E:$E,"Mathematics"),0),"") | F11: =IFERROR(ROUND(AVERAGEIFS(Assessments!$J:$J,Assessments!$C:$C,"Lower",Assessments!$K:$K,"Upper Primary",Assessments!$D:$D,"Grade 6 – A",Assessments!$E:$E,"Science"),0),"") | G11: =IFERROR(ROUND(AVERAGEIFS(Assessments!$J:$J,Assessments!$C:$C,"Lower",Assessments!$K:$K,"Upper Primary",Assessments!$D:$D,"Grade 6 – A",Assessments!$E:$E,"Integrated Science"),0),"") | H11: =IFERROR(ROUND(AVERAGEIFS(Assessments!$J:$J,Assessments!$C:$C,"Lower",Assessments!$K:$K,"Upper Primary",Assessments!$D:$D,"Grade 6 – A",Assessments!$E:$E,"Social Studies"),0),"") | I11: =IFERROR(ROUND(AVERAGEIFS(Assessments!$J:$J,Assessments!$C:$C,"Lower",Assessments!$K:$K,"Upper Primary",Assessments!$D:$D,"Grade 6 – A",Assessments!$E:$E,"CRE"),0),"") | J11: =IFERROR(ROUND(AVERAGEIFS(Assessments!$J:$J,Assessments!$C:$C,"Lower",Assessments!$K:$K,"Upper Primary",Assessments!$D:$D,"Grade 6 – A",Assessments!$E:$E,"Computer Studies"),0),"") | K11: =IFERROR(ROUND(AVERAGEIFS(Assessments!$J:$J,Assessments!$C:$C,"Lower",Assessments!$K:$K,"Upper Primary",Assessments!$D:$D,"Grade 6 – A"),0),"")
A12: Upper Primary | B12: Grade 6 – B | C12: =IFERROR(ROUND(AVERAGEIFS(Assessments!$J:$J,Assessments!$C:$C,"Lower",Assessments!$K:$K,"Upper Primary",Assessments!$D:$D,"Grade 6 – B",Assessments!$E:$E,"English"),0),"") | D12: =IFERROR(ROUND(AVERAGEIFS(Assessments!$J:$J,Assessments!$C:$C,"Lower",Assessments!$K:$K,"Upper Primary",Assessments!$D:$D,"Grade 6 – B",Assessments!$E:$E,"Kiswahili"),0),"") | E12: =IFERROR(ROUND(AVERAGEIFS(Assessments!$J:$J,Assessments!$C:$C,"Lower",Assessments!$K:$K,"Upper Primary",Assessments!$D:$D,"Grade 6 – B",Assessments!$E:$E,"Mathematics"),0),"") | F12: =IFERROR(ROUND(AVERAGEIFS(Assessments!$J:$J,Assessments!$C:$C,"Lower",Assessments!$K:$K,"Upper Primary",Assessments!$D:$D,"Grade 6 – B",Assessments!$E:$E,"Science"),0),"") | G12: =IFERROR(ROUND(AVERAGEIFS(Assessments!$J:$J,Assessments!$C:$C,"Lower",Assessments!$K:$K,"Upper Primary",Assessments!$D:$D,"Grade 6 – B",Assessments!$E:$E,"Integrated Science"),0),"") | H12: =IFERROR(ROUND(AVERAGEIFS(Assessments!$J:$J,Assessments!$C:$C,"Lower",Assessments!$K:$K,"Upper Primary",Assessments!$D:$D,"Grade 6 – B",Assessments!$E:$E,"Social Studies"),0),"") | I12: =IFERROR(ROUND(AVERAGEIFS(Assessments!$J:$J,Assessments!$C:$C,"Lower",Assessments!$K:$K,"Upper Primary",Assessments!$D:$D,"Grade 6 – B",Assessments!$E:$E,"CRE"),0),"") | J12: =IFERROR(ROUND(AVERAGEIFS(Assessments!$J:$J,Assessments!$C:$C,"Lower",Assessments!$K:$K,"Upper Primary",Assessments!$D:$D,"Grade 6 – B",Assessments!$E:$E,"Computer Studies"),0),"") | K12: =IFERROR(ROUND(AVERAGEIFS(Assessments!$J:$J,Assessments!$C:$C,"Lower",Assessments!$K:$K,"Upper Primary",Assessments!$D:$D,"Grade 6 – B"),0),"")
A13: Junior School | B13: Grade 7 – A | C13: =IFERROR(ROUND(AVERAGEIFS(Assessments!$J:$J,Assessments!$C:$C,"Lower",Assessments!$K:$K,"Junior School",Assessments!$D:$D,"Grade 7 – A",Assessments!$E:$E,"English"),0),"") | D13: =IFERROR(ROUND(AVERAGEIFS(Assessments!$J:$J,Assessments!$C:$C,"Lower",Assessments!$K:$K,"Junior School",Assessments!$D:$D,"Grade 7 – A",Assessments!$E:$E,"Kiswahili"),0),"") | E13: =IFERROR(ROUND(AVERAGEIFS(Assessments!$J:$J,Assessments!$C:$C,"Lower",Assessments!$K:$K,"Junior School",Assessments!$D:$D,"Grade 7 – A",Assessments!$E:$E,"Mathematics"),0),"") | F13: =IFERROR(ROUND(AVERAGEIFS(Assessments!$J:$J,Assessments!$C:$C,"Lower",Assessments!$K:$K,"Junior School",Assessments!$D:$D,"Grade 7 – A",Assessments!$E:$E,"Science"),0),"") | G13: =IFERROR(ROUND(AVERAGEIFS(Assessments!$J:$J,Assessments!$C:$C,"Lower",Assessments!$K:$K,"Junior School",Assessments!$D:$D,"Grade 7 – A",Assessments!$E:$E,"Integrated Science"),0),"") | H13: =IFERROR(ROUND(AVERAGEIFS(Assessments!$J:$J,Assessments!$C:$C,"Lower",Assessments!$K:$K,"Junior School",Assessments!$D:$D,"Grade 7 – A",Assessments!$E:$E,"Social Studies"),0),"") | I13: =IFERROR(ROUND(AVERAGEIFS(Assessments!$J:$J,Assessments!$C:$C,"Lower",Assessments!$K:$K,"Junior School",Assessments!$D:$D,"Grade 7 – A",Assessments!$E:$E,"CRE"),0),"") | J13: =IFERROR(ROUND(AVERAGEIFS(Assessments!$J:$J,Assessments!$C:$C,"Lower",Assessments!$K:$K,"Junior School",Assessments!$D:$D,"Grade 7 – A",Assessments!$E:$E,"Computer Studies"),0),"") | K13: =IFERROR(ROUND(AVERAGEIFS(Assessments!$J:$J,Assessments!$C:$C,"Lower",Assessments!$K:$K,"Junior School",Assessments!$D:$D,"Grade 7 – A"),0),"")
A14: Junior School | B14: Grade 7 – B | C14: =IFERROR(ROUND(AVERAGEIFS(Assessments!$J:$J,Assessments!$C:$C,"Lower",Assessments!$K:$K,"Junior School",Assessments!$D:$D,"Grade 7 – B",Assessments!$E:$E,"English"),0),"") | D14: =IFERROR(ROUND(AVERAGEIFS(Assessments!$J:$J,Assessments!$C:$C,"Lower",Assessments!$K:$K,"Junior School",Assessments!$D:$D,"Grade 7 – B",Assessments!$E:$E,"Kiswahili"),0),"") | E14: =IFERROR(ROUND(AVERAGEIFS(Assessments!$J:$J,Assessments!$C:$C,"Lower",Assessments!$K:$K,"Junior School",Assessments!$D:$D,"Grade 7 – B",Assessments!$E:$E,"Mathematics"),0),"") | F14: =IFERROR(ROUND(AVERAGEIFS(Assessments!$J:$J,Assessments!$C:$C,"Lower",Assessments!$K:$K,"Junior School",Assessments!$D:$D,"Grade 7 – B",Assessments!$E:$E,"Science"),0),"") | G14: =IFERROR(ROUND(AVERAGEIFS(Assessments!$J:$J,Assessments!$C:$C,"Lower",Assessments!$K:$K,"Junior School",Assessments!$D:$D,"Grade 7 – B",Assessments!$E:$E,"Integrated Science"),0),"") | H14: =IFERROR(ROUND(AVERAGEIFS(Assessments!$J:$J,Assessments!$C:$C,"Lower",Assessments!$K:$K,"Junior School",Assessments!$D:$D,"Grade 7 – B",Assessments!$E:$E,"Social Studies"),0),"") | I14: =IFERROR(ROUND(AVERAGEIFS(Assessments!$J:$J,Assessments!$C:$C,"Lower",Assessments!$K:$K,"Junior School",Assessments!$D:$D,"Grade 7 – B",Assessments!$E:$E,"CRE"),0),"") | J14: =IFERROR(ROUND(AVERAGEIFS(Assessments!$J:$J,Assessments!$C:$C,"Lower",Assessments!$K:$K,"Junior School",Assessments!$D:$D,"Grade 7 – B",Assessments!$E:$E,"Computer Studies"),0),"") | K14: =IFERROR(ROUND(AVERAGEIFS(Assessments!$J:$J,Assessments!$C:$C,"Lower",Assessments!$K:$K,"Junior School",Assessments!$D:$D,"Grade 7 – B"),0),"")
A15: Junior School | B15: Grade 8 – A | C15: =IFERROR(ROUND(AVERAGEIFS(Assessments!$J:$J,Assessments!$C:$C,"Lower",Assessments!$K:$K,"Junior School",Assessments!$D:$D,"Grade 8 – A",Assessments!$E:$E,"English"),0),"") | D15: =IFERROR(ROUND(AVERAGEIFS(Assessments!$J:$J,Assessments!$C:$C,"Lower",Assessments!$K:$K,"Junior School",Assessments!$D:$D,"Grade 8 – A",Assessments!$E:$E,"Kiswahili"),0),"") | E15: =IFERROR(ROUND(AVERAGEIFS(Assessments!$J:$J,Assessments!$C:$C,"Lower",Assessments!$K:$K,"Junior School",Assessments!$D:$D,"Grade 8 – A",Assessments!$E:$E,"Mathematics"),0),"") | F15: =IFERROR(ROUND(AVERAGEIFS(Assessments!$J:$J,Assessments!$C:$C,"Lower",Assessments!$K:$K,"Junior School",Assessments!$D:$D,"Grade 8 – A",Assessments!$E:$E,"Science"),0),"") | G15: =IFERROR(ROUND(AVERAGEIFS(Assessments!$J:$J,Assessments!$C:$C,"Lower",Assessments!$K:$K,"Junior School",Assessments!$D:$D,"Grade 8 – A",Assessments!$E:$E,"Integrated Science"),0),"") | H15: =IFERROR(ROUND(AVERAGEIFS(Assessments!$J:$J,Assessments!$C:$C,"Lower",Assessments!$K:$K,"Junior School",Assessments!$D:$D,"Grade 8 – A",Assessments!$E:$E,"Social Studies"),0),"") | I15: =IFERROR(ROUND(AVERAGEIFS(Assessments!$J:$J,Assessments!$C:$C,"Lower",Assessments!$K:$K,"Junior School",Assessments!$D:$D,"Grade 8 – A",Assessments!$E:$E,"CRE"),0),"") | J15: =IFERROR(ROUND(AVERAGEIFS(Assessments!$J:$J,Assessments!$C:$C,"Lower",Assessments!$K:$K,"Junior School",Assessments!$D:$D,"Grade 8 – A",Assessments!$E:$E,"Computer Studies"),0),"") | K15: =IFERROR(ROUND(AVERAGEIFS(Assessments!$J:$J,Assessments!$C:$C,"Lower",Assessments!$K:$K,"Junior School",Assessments!$D:$D,"Grade 8 – A"),0),"")
A16: Junior School | B16: Grade 8 – B | C16: =IFERROR(ROUND(AVERAGEIFS(Assessments!$J:$J,Assessments!$C:$C,"Lower",Assessments!$K:$K,"Junior School",Assessments!$D:$D,"Grade 8 – B",Assessments!$E:$E,"English"),0),"") | D16: =IFERROR(ROUND(AVERAGEIFS(Assessments!$J:$J,Assessments!$C:$C,"Lower",Assessments!$K:$K,"Junior School",Assessments!$D:$D,"Grade 8 – B",Assessments!$E:$E,"Kiswahili"),0),"") | E16: =IFERROR(ROUND(AVERAGEIFS(Assessments!$J:$J,Assessments!$C:$C,"Lower",Assessments!$K:$K,"Junior School",Assessments!$D:$D,"Grade 8 – B",Assessments!$E:$E,"Mathematics"),0),"") | F16: =IFERROR(ROUND(AVERAGEIFS(Assessments!$J:$J,Assessments!$C:$C,"Lower",Assessments!$K:$K,"Junior School",Assessments!$D:$D,"Grade 8 – B",Assessments!$E:$E,"Science"),0),"") | G16: =IFERROR(ROUND(AVERAGEIFS(Assessments!$J:$J,Assessments!$C:$C,"Lower",Assessments!$K:$K,"Junior School",Assessments!$D:$D,"Grade 8 – B",Assessments!$E:$E,"Integrated Science"),0),"") | H16: =IFERROR(ROUND(AVERAGEIFS(Assessments!$J:$J,Assessments!$C:$C,"Lower",Assessments!$K:$K,"Junior School",Assessments!$D:$D,"Grade 8 – B",Assessments!$E:$E,"Social Studies"),0),"") | I16: =IFERROR(ROUND(AVERAGEIFS(Assessments!$J:$J,Assessments!$C:$C,"Lower",Assessments!$K:$K,"Junior School",Assessments!$D:$D,"Grade 8 – B",Assessments!$E:$E,"CRE"),0),"") | J16: =IFERROR(ROUND(AVERAGEIFS(Assessments!$J:$J,Assessments!$C:$C,"Lower",Assessments!$K:$K,"Junior School",Assessments!$D:$D,"Grade 8 – B",Assessments!$E:$E,"Computer Studies"),0),"") | K16: =IFERROR(ROUND(AVERAGEIFS(Assessments!$J:$J,Assessments!$C:$C,"Lower",Assessments!$K:$K,"Junior School",Assessments!$D:$D,"Grade 8 – B"),0),"")
A17: Junior School | B17: Grade 9 – A | C17: =IFERROR(ROUND(AVERAGEIFS(Assessments!$J:$J,Assessments!$C:$C,"Lower",Assessments!$K:$K,"Junior School",Assessments!$D:$D,"Grade 9 – A",Assessments!$E:$E,"English"),0),"") | D17: =IFERROR(ROUND(AVERAGEIFS(Assessments!$J:$J,Assessments!$C:$C,"Lower",Assessments!$K:$K,"Junior School",Assessments!$D:$D,"Grade 9 – A",Assessments!$E:$E,"Kiswahili"),0),"") | E17: =IFERROR(ROUND(AVERAGEIFS(Assessments!$J:$J,Assessments!$C:$C,"Lower",Assessments!$K:$K,"Junior School",Assessments!$D:$D,"Grade 9 – A",Assessments!$E:$E,"Mathematics"),0),"") | F17: =IFERROR(ROUND(AVERAGEIFS(Assessments!$J:$J,Assessments!$C:$C,"Lower",Assessments!$K:$K,"Junior School",Assessments!$D:$D,"Grade 9 – A",Assessments!$E:$E,"Science"),0),"") | G17: =IFERROR(ROUND(AVERAGEIFS(Assessments!$J:$J,Assessments!$C:$C,"Lower",Assessments!$K:$K,"Junior School",Assessments!$D:$D,"Grade 9 – A",Assessments!$E:$E,"Integrated Science"),0),"") | H17: =IFERROR(ROUND(AVERAGEIFS(Assessments!$J:$J,Assessments!$C:$C,"Lower",Assessments!$K:$K,"Junior School",Assessments!$D:$D,"Grade 9 – A",Assessments!$E:$E,"Social Studies"),0),"") | I17: =IFERROR(ROUND(AVERAGEIFS(Assessments!$J:$J,Assessments!$C:$C,"Lower",Assessments!$K:$K,"Junior School",Assessments!$D:$D,"Grade 9 – A",Assessments!$E:$E,"CRE"),0),"") | J17: =IFERROR(ROUND(AVERAGEIFS(Assessments!$J:$J,Assessments!$C:$C,"Lower",Assessments!$K:$K,"Junior School",Assessments!$D:$D,"Grade 9 – A",Assessments!$E:$E,"Computer Studies"),0),"") | K17: =IFERROR(ROUND(AVERAGEIFS(Assessments!$J:$J,Assessments!$C:$C,"Lower",Assessments!$K:$K,"Junior School",Assessments!$D:$D,"Grade 9 – A"),0),"")
A18: Junior School | B18: Grade 9 – B | C18: =IFERROR(ROUND(AVERAGEIFS(Assessments!$J:$J,Assessments!$C:$C,"Lower",Assessments!$K:$K,"Junior School",Assessments!$D:$D,"Grade 9 – B",Assessments!$E:$E,"English"),0),"") | D18: =IFERROR(ROUND(AVERAGEIFS(Assessments!$J:$J,Assessments!$C:$C,"Lower",Assessments!$K:$K,"Junior School",Assessments!$D:$D,"Grade 9 – B",Assessments!$E:$E,"Kiswahili"),0),"") | E18: =IFERROR(ROUND(AVERAGEIFS(Assessments!$J:$J,Assessments!$C:$C,"Lower",Assessments!$K:$K,"Junior School",Assessments!$D:$D,"Grade 9 – B",Assessments!$E:$E,"Mathematics"),0),"") | F18: =IFERROR(ROUND(AVERAGEIFS(Assessments!$J:$J,Assessments!$C:$C,"Lower",Assessments!$K:$K,"Junior School",Assessments!$D:$D,"Grade 9 – B",Assessments!$E:$E,"Science"),0),"") | G18: =IFERROR(ROUND(AVERAGEIFS(Assessments!$J:$J,Assessments!$C:$C,"Lower",Assessments!$K:$K,"Junior School",Assessments!$D:$D,"Grade 9 – B",Assessments!$E:$E,"Integrated Science"),0),"") | H18: =IFERROR(ROUND(AVERAGEIFS(Assessments!$J:$J,Assessments!$C:$C,"Lower",Assessments!$K:$K,"Junior School",Assessments!$D:$D,"Grade 9 – B",Assessments!$E:$E,"Social Studies"),0),"") | I18: =IFERROR(ROUND(AVERAGEIFS(Assessments!$J:$J,Assessments!$C:$C,"Lower",Assessments!$K:$K,"Junior School",Assessments!$D:$D,"Grade 9 – B",Assessments!$E:$E,"CRE"),0),"") | J18: =IFERROR(ROUND(AVERAGEIFS(Assessments!$J:$J,Assessments!$C:$C,"Lower",Assessments!$K:$K,"Junior School",Assessments!$D:$D,"Grade 9 – B",Assessments!$E:$E,"Computer Studies"),0),"") | K18: =IFERROR(ROUND(AVERAGEIFS(Assessments!$J:$J,Assessments!$C:$C,"Lower",Assessments!$K:$K,"Junior School",Assessments!$D:$D,"Grade 9 – B"),0),"")

Sheet Students
A1: Student Name (enter once, used for dropdowns) | B1: Campus (Upper/Lower) | C1: Class

Sheet Teachers
A1: Teacher Name (enter once, used for dropdowns) | B1: Campus (Upper/Lower) [optional]

Sheet Class Reports
A1: Week Ending | B1: Campus (Upper/Lower) | C1: Class | D1: Class Teacher | E1: Total Learners | F1: Frequent Absentees (No.) | G1: Discipline Level (Excellent/Good/Fair/Poor) | H1: Homework Completion (High/Medium/Low) | I1: Learners Struggling (No.) | J1: Learners Improved (No.) | K1: Parents to Contact (No.) | L1: Classroom Condition (Good/Fair/Poor) | M1: Notes | N1: Academic Group
N2: =IF(C2="","",IFERROR(INDEX(Classes!$B$2:$B$200,MATCH(C2,Classes!$E$2:$E$200,0)),""))
N3: =IF(C3="","",IFERROR(INDEX(Classes!$B$2:$B$200,MATCH(C3,Classes!$E$2:$E$200,0)),""))
N4: =IF(C4="","",IFERROR(INDEX(Classes!$B$2:$B$200,MATCH(C4,Classes!$E$2:$E$200,0)),""))
N5: =IF(C5="","",IFERROR(INDEX(Classes!$B$2:$B$200,MATCH(C5,Classes!$E$2:$E$200,0)),""))
N6: =IF(C6="","",IFERROR(INDEX(Classes!$B$2:$B$200,MATCH(C6,Classes!$E$2:$E$200,0)),""))
N7: =IF(C7="","",IFERROR(INDEX(Classes!$B$2:$B$200,MATCH(C7,Classes!$E$2:$E$200,0)),""))
N8: =IF(C8="","",IFERROR(INDEX(Classes!$B$2:$B$200,MATCH(C8,Classes!$E$2:$E$200,0)),""))
N9: =IF(C9="","",IFERROR(INDEX(Classes!$B$2:$B$200,MATCH(C9,Classes!$E$2:$E$200,0)),""))
N10: =IF(C10="","",IFERROR(INDEX(Classes!$B$2:$B$200,MATCH(C10,Classes!$E$2:$E$200,0)),""))
N11: =IF(C11="","",IFERROR(INDEX(Classes!$B$2:$B$200,MATCH(C11,Classes!$E$2:$E$200,0)),""))
N12: =IF(C12="","",IFERROR(INDEX(Classes!$B$2:$B$200,MATCH(C12,Classes!$E$2:$E$200,0)),""))
N13: =IF(C13="","",IFERROR(INDEX(Classes!$B$2:$B$200,MATCH(C13,Classes!$E$2:$E$200,0)),""))
... N500: =IF(C500="","",IFERROR(INDEX(Classes!$B$2:$B$200,MATCH(C500,Classes!$E$2:$E$200,0)),""))

Sheet Subject Reports
A1: Week Ending | B1: Campus (Upper/Lower) | C1: Subject | D1: Teacher | E1: Class | F1: Topics Covered | G1: Syllabus Status (On Track/Slightly Behind/Behind) | H1: Strong % | I1: Average % | J1: Struggling % | K1: Homework Given (Yes/No) | L1: Test Done (Yes/No) | M1: Marking Done (Yes/No) | N1: Main Challenge | O1: Support Needed | P1: Academic Group
P2: =IF(E2="","",IFERROR(INDEX(Classes!$B$2:$B$200,MATCH(E2,Classes!$E$2:$E$200,0)),""))
P3: =IF(E3="","",IFERROR(INDEX(Classes!$B$2:$B$200,MATCH(E3,Classes!$E$2:$E$200,0)),""))
P4: =IF(E4="","",IFERROR(INDEX(Classes!$B$2:$B$200,MATCH(E4,Classes!$E$2:$E$200,0)),""))
P5: =IF(E5="","",IFERROR(INDEX(Classes!$B$2:$B$200,MATCH(E5,Classes!$E$2:$E$200,0)),""))
P6: =IF(E6="","",IFERROR(INDEX(Classes!$B$2:$B$200,MATCH(E6,Classes!$E$2:$E$200,0)),""))
P7: =IF(E7="","",IFERROR(INDEX(Classes!$B$2:$B$200,MATCH(E7,Classes!$E$2:$E$200,0)),""))
P8: =IF(E8="","",IFERROR(INDEX(Classes!$B$2:$B$200,MATCH(E8,Classes!$E$2:$E$200,0)),""))
P9: =IF(E9="","",IFERROR(INDEX(Classes!$B$2:$B$200,MATCH(E9,Classes!$E$2:$E$200,0)),""))
P10: =IF(E10="","",IFERROR(INDEX(Classes!$B$2:$B$200,MATCH(E10,Classes!$E$2:$E$200,0)),""))
P11: =IF(E11="","",IFERROR(INDEX(Classes!$B$2:$B$200,MATCH(E11,Classes!$E$2:$E$200,0)),""))
P12: =IF(E12="","",IFERROR(INDEX(Classes!$B$2:$B$200,MATCH(E12,Classes!$E$2:$E$200,0)),""))
P13: =IF(E13="","",IFERROR(INDEX(Classes!$B$2:$B$200,MATCH(E13,Classes!$E$2:$E$200,0)),""))
... P500: =IF(E500="","",IFERROR(INDEX(Classes!$B$2:$B$200,MATCH(E500,Classes!$E$2:$E$200,0)),""))

Sheet Staff Weekly
A1: Week Ending | B1: Campus (Upper/Lower) | C1: Teacher Name | D1: On Time All Week (Yes/No) | E1: Lessons Missed (No.) | F1: Books Marked (Yes/No) | G1: Schemes Updated (Yes/No) | H1: Class Control (Good/Fair/Poor) | I1: General Performance (Excellent/Good/Fair/Poor) | J1: Notes

Sheet Student Follow-Up
A1: Week Ending | B1: Campus (Upper/Lower) | C1: Student Name | D1: Class | E1: Academic Concern (Yes/No) | F1: Behavior Concern (Yes/No) | G1: Action Taken | H1: Parent Contacted (Yes/No) | I1: Progress Status (Improving/Same/Worse) | J1: Notes

Sheet Operations & Facilities
A1: Week Ending | B1: Campus (Upper/Lower) | C1: Area (Toilets/Classrooms/Desks/Kitchen/Water/Transport/Security) | D1: Status (Good/Fair/Poor) | E1: Issue Noted | F1: Action Needed | G1: Responsible Person | H1: Resolved (Yes/No) | I1: Notes

Sheet Director Dashboard
A1: Selected Week Ending (type date exactly as in sheets)
A3: Key Weekly Alerts (Selected Week)
A4: Metric | B4: Count
A5: Classes with Poor Discipline | B5: =COUNTIFS('Class Reports'!A:A,$B$1,'Class Reports'!G:G,"Poor")
A6: Classes with Low Homework | B6: =COUNTIFS('Class Reports'!A:A,$B$1,'Class Reports'!H:H,"Low")
A7: Subjects Behind Syllabus | B7: =COUNTIFS('Subject Reports'!A:A,$B$1,'Subject Reports'!G:G,"Behind")
A8: Teachers Not Marking Books | B8: =COUNTIFS('Staff Weekly'!A:A,$B$1,'Staff Weekly'!F:F,"No")
A9: Students with Academic Concerns | B9: =COUNTIFS('Student Follow-Up'!A:A,$B$1,'Student Follow-Up'!E:E,"Yes")
A10: Unresolved Facility Issues | B10: =COUNTIFS('Operations & Facilities'!A:A,$B$1,'Operations & Facilities'!H:H,"No")

Sheet Term Summary
A1: Week | B1: Week Ending Date | C1: Subjects Behind | D1: Poor Discipline Classes | E1: Low Homework Classes | F1: Teachers Not Marking | G1: Facility Areas Poor | H1: Overall Score % | I1: Overall Rating | J1: Upper Campus Score % | K1: Lower Campus Score % | M1: Targets (Max acceptable per week)
A2: Week 1 | C2: =COUNTIFS('Subject Reports'!A:A,$B2,'Subject Reports'!G:G,"Behind") | D2: =COUNTIFS('Class Reports'!A:A,$B2,'Class Reports'!G:G,"Poor") | E2: =COUNTIFS('Class Reports'!A:A,$B2,'Class Reports'!H:H,"Low") | F2: =COUNTIFS('Staff Weekly'!A:A,$B2,'Staff Weekly'!F:F,"No") | G2: =COUNTIFS('Operations & Facilities'!A:A,$B2,'Operations & Facilities'!D:D,"Poor") | H2: =ROUND(100*(((1-MIN(1,C2/$N$2))+(1-MIN(1,D2/$N$3))+(1-MIN(1,E2/$N$4))+(1-MIN(1,F2/$N$5))+(1-MIN(1,G2/$N$6)))/5),0) | I2: =IF(H2>=90,"Excellent",IF(H2>=75,"Good",IF(H2>=60,"Fair","Needs Improvement"))) | J2: =ROUND(100*(((1-MIN(1,COUNTIFS('Subject Reports'!A:A,$B2,'Subject Reports'!B:B,"Upper",'Subject Reports'!G:G,"Behind")/$N$2))+(1-MIN(1,COUNTIFS('Class Reports'!A:A,$B2,'Class Reports'!B:B,"Upper",'Class Reports'!G:G,"Poor")/$N$3))+(1-MIN(1,COUNTIFS('Class Reports'!A:A,$B2,'Class Reports'!B:B,"Upper",'Class Reports'!H:H,"Low")/$N$4))+(1-MIN(1,COUNTIFS('Staff Weekly'!A:A,$B2,'Staff Weekly'!B:B,"Upper",'Staff Weekly'!F:F,"No")/$N$5))+(1-MIN(1,COUNTIFS('Operations & Facilities'!A:A,$B2,'Operations & Facilities'!B:B,"Upper",'Operations & Facilities'!D:D,"Poor")/$N$6)))/5),0) | K2: =ROUND(100*(((1-MIN(1,COUNTIFS('Subject Reports'!A:A,$B2,'Subject Reports'!B:B,"Lower",'Subject Reports'!G:G,"Behind")/$N$2))+(1-MIN(1,COUNTIFS('Class Reports'!A:A,$B2,'Class Reports'!B:B,"Lower",'Class Reports'!G:G,"Poor")/$N$3))+(1-MIN(1,COUNTIFS('Class Reports'!A:A,$B2,'Class Reports'!B:B,"Lower",'Class Reports'!H:H,"Low")/$N$4))+(1-MIN(1,COUNTIFS('Staff Weekly'!A:A,$B2,'Staff Weekly'!B:B,"Lower",'Staff Weekly'!F:F,"No")/$N$5))+(1-MIN(1,COUNTIFS('Operations & Facilities'!A:A,$B2,'Operations & Facilities'!B:B,"Lower",'Operations & Facilities'!D:D,"Poor")/$N$6)))/5),0) | M2: Subjects Behind | N2: 3
A3: Week 2 | C3: =COUNTIFS('Subject Reports'!A:A,$B3,'Subject Reports'!G:G,"Behind") | D3: =COUNTIFS('Class Reports'!A:A,$B3,'Class Reports'!G:G,"Poor") | E3: =COUNTIFS('Class Reports'!A:A,$B3,'Class Reports'!H:H,"Low") | F3: =COUNTIFS('Staff Weekly'!A:A,$B3,'Staff Weekly'!F:F,"No") | G3: =COUNTIFS('Operations & Facilities'!A:A,$B3,'Operations & Facilities'!D:D,"Poor") | H3: =ROUND(100*(((1-MIN(1,C3/$N$2))+(1-MIN(1,D3/$N$3))+(1-MIN(1,E3/$N$4))+(1-MIN(1,F3/$N$5))+(1-MIN(1,G3/$N$6)))/5),0) | I3: =IF(H3>=90,"Excellent",IF(H3>=75,"Good",IF(H3>=60,"Fair","Needs Improvement"))) | J3: =ROUND(100*(((1-MIN(1,COUNTIFS('Subject Reports'!A:A,$B3,'Subject Reports'!B:B,"Upper",'Subject Reports'!G:G,"Behind")/$N$2))+(1-MIN(1,COUNTIFS('Class Reports'!A:A,$B3,'Class Reports'!B:B,"Upper",'Class Reports'!G:G,"Poor")/$N$3))+(1-MIN(1,COUNTIFS('Class Reports'!A:A,$B3,'Class Reports'!B:B,"Upper",'Class Reports'!H:H,"Low")/$N$4))+(1-MIN(1,COUNTIFS('Staff Weekly'!A:A,$B3,'Staff Weekly'!B:B,"Upper",'Staff Weekly'!F:F,"No")/$N$5))+(1-MIN(1,COUNTIFS('Operations & Facilities'!A:A,$B3,'Operations & Facilities'!B:B,"Upper",'Operations & Facilities'!D:D,"Poor")/$N$6)))/5),0) | K3: =ROUND(100*(((1-MIN(1,COUNTIFS('Subject Reports'!A:A,$B3,'Subject Reports'!B:B,"Lower",'Subject Reports'!G:G,"Behind")/$N$2))+(1-MIN(1,COUNTIFS('Class Reports'!A:A,$B3,'Class Reports'!B:B,"Lower",'Class Reports'!G:G,"Poor")/$N$3))+(1-MIN(1,COUNTIFS('Class Reports'!A:A,$B3,'Class Reports'!B:B,"Lower",'Class Reports'!H:H,"Low")/$N$4))+(1-MIN(1,COUNTIFS('Staff Weekly'!A:A,$B3,'Staff Weekly'!B:B,"Lower",'Staff Weekly'!F:F,"No")/$N$5))+(1-MIN(1,COUNTIFS('Operations & Facilities'!A:A,$B3,'Operations & Facilities'!B:B,"Lower",'Operations & Facilities'!D:D,"Poor")/$N$6)))/5),0) | M3: Poor Discipline | N3: 1
A4: Week 3 | C4: =COUNTIFS('Subject Reports'!A:A,$B4,'Subject Reports'!G:G,"Behind") | D4: =COUNTIFS('Class Reports'!A:A,$B4,'Class Reports'!G:G,"Poor") | E4: =COUNTIFS('Class Reports'!A:A,$B4,'Class Reports'!H:H,"Low") | F4: =COUNTIFS('Staff Weekly'!A:A,$B4,'Staff Weekly'!F:F,"No") | G4: =COUNTIFS('Operations & Facilities'!A:A,$B4,'Operations & Facilities'!D:D,"Poor") | H4: =ROUND(100*(((1-MIN(1,C4/$N$2))+(1-MIN(1,D4/$N$3))+(1-MIN(1,E4/$N$4))+(1-MIN(1,F4/$N$5))+(1-MIN(1,G4/$N$6)))/5),0) | I4: =IF(H4>=90,"Excellent",IF(H4>=75,"Good",IF(H4>=60,"Fair","Needs Improvement"))) | J4: =ROUND(100*(((1-MIN(1,COUNTIFS('Subject Reports'!A:A,$B4,'Subject Reports'!B:B,"Upper",'Subject Reports'!G:G,"Behind")/$N$2))+(1-MIN(1,COUNTIFS('Class Reports'!A:A,$B4,'Class Reports'!B:B,"Upper",'Class Reports'!G:G,"Poor")/$N$3))+(1-MIN(1,COUNTIFS('Class Reports'!A:A,$B4,'Class Reports'!B:B,"Upper",'Class Reports'!H:H,"Low")/$N$4))+(1-MIN(1,COUNTIFS('Staff Weekly'!A:A,$B4,'Staff Weekly'!B:B,"Upper",'Staff Weekly'!F:F,"No")/$N$5))+(1-MIN(1,COUNTIFS('Operations & Facilities'!A:A,$B4,'Operations & Facilities'!B:B,"Upper",'Operations & Facilities'!D:D,"Poor")/$N$6)))/5),0) | K4: =ROUND(100*(((1-MIN(1,COUNTIFS('Subject Reports'!A:A,$B4,'Subject Reports'!B:B,"Lower",'Subject Reports'!G:G,"Behind")/$N$2))+(1-MIN(1,COUNTIFS('Class Reports'!A:A,$B4,'Class Reports'!B:B,"Lower",'Class Reports'!G:G,"Poor")/$N$3))+(1-MIN(1,COUNTIFS('Class Reports'!A:A,$B4,'Class Reports'!B:B,"Lower",'Class Reports'!H:H,"Low")/$N$4))+(1-MIN(1,COUNTIFS('Staff Weekly'!A:A,$B4,'Staff Weekly'!B:B,"Lower",'Staff Weekly'!F:F,"No")/$N$5))+(1-MIN(1,COUNTIFS('Operations & Facilities'!A:A,$B4,'Operations & Facilities'!B:B,"Lower",'Operations & Facilities'!D:D,"Poor")/$N$6)))/5),0) | M4: Low Homework | N4: 2
A5: Week 4 | C5: =COUNTIFS('Subject Reports'!A:A,$B5,'Subject Reports'!G:G,"Behind") | D5: =COUNTIFS('Class Reports'!A:A,$B5,'Class Reports'!G:G,"Poor") | E5: =COUNTIFS('Class Reports'!A:A,$B5,'Class Reports'!H:H,"Low") | F5: =COUNTIFS('Staff Weekly'!A:A,$B5,'Staff Weekly'!F:F,"No") | G5: =COUNTIFS('Operations & Facilities'!A:A,$B5,'Operations & Facilities'!D:D,"Poor") | H5: =ROUND(100*(((1-MIN(1,C5/$N$2))+(1-MIN(1,D5/$N$3))+(1-MIN(1,E5/$N$4))+(1-MIN(1,F5/$N$5))+(1-MIN(1,G5/$N$6)))/5),0) | I5: =IF(H5>=90,"Excellent",IF(H5>=75,"Good",IF(H5>=60,"Fair","Needs Improvement"))) | J5: =ROUND(100*(((1-MIN(1,COUNTIFS('Subject Reports'!A:A,$B5,'Subject Reports'!B:B,"Upper",'Subject Reports'!G:G,"Behind")/$N$2))+(1-MIN(1,COUNTIFS('Class Reports'!A:A,$B5,'Class Reports'!B:B,"Upper",'Class Reports'!G:G,"Poor")/$N$3))+(1-MIN(1,COUNTIFS('Class Reports'!A:A,$B5,'Class Reports'!B:B,"Upper",'Class Reports'!H:H,"Low")/$N$4))+(1-MIN(1,COUNTIFS('Staff Weekly'!A:A,$B5,'Staff Weekly'!B:B,"Upper",'Staff Weekly'!F:F,"No")/$N$5))+(1-MIN(1,COUNTIFS('Operations & Facilities'!A:A,$B5,'Operations & Facilities'!B:B,"Upper",'Operations & Facilities'!D:D,"Poor")/$N$6)))/5),0) | K5: =ROUND(100*(((1-MIN(1,COUNTIFS('Subject Reports'!A:A,$B5,'Subject Reports'!B:B,"Lower",'Subject Reports'!G:G,"Behind")/$N$2))+(1-MIN(1,COUNTIFS('Class Reports'!A:A,$B5,'Class Reports'!B:B,"Lower",'Class Reports'!G:G,"Poor")/$N$3))+(1-MIN(1,COUNTIFS('Class Reports'!A:A,$B5,'Class Reports'!B:B,"Lower",'Class Reports'!H:H,"Low")/$N$4))+(1-MIN(1,COUNTIFS('Staff Weekly'!A:A,$B5,'Staff Weekly'!B:B,"Lower",'Staff Weekly'!F:F,"No")/$N$5))+(1-MIN(1,COUNTIFS('Operations & Facilities'!A:A,$B5,'Operations & Facilities'!B:B,"Lower",'Operations & Facilities'!D:D,"Poor")/$N$6)))/5),0) | M5: Not Marking | N5: 1
A6: Week 5 | C6: =COUNTIFS('Subject Reports'!A:A,$B6,'Subject Reports'!G:G,"Behind") | D6: =COUNTIFS('Class Reports'!A:A,$B6,'Class Reports'!G:G,"Poor") | E6: =COUNTIFS('Class Reports'!A:A,$B6,'Class Reports'!H:H,"Low") | F6: =COUNTIFS('Staff Weekly'!A:A,$B6,'Staff Weekly'!F:F,"No") | G6: =COUNTIFS('Operations & Facilities'!A:A,$B6,'Operations & Facilities'!D:D,"Poor") | H6: =ROUND(100*(((1-MIN(1,C6/$N$2))+(1-MIN(1,D6/$N$3))+(1-MIN(1,E6/$N$4))+(1-MIN(1,F6/$N$5))+(1-MIN(1,G6/$N$6)))/5),0) | I6: =IF(H6>=90,"Excellent",IF(H6>=75,"Good",IF(H6>=60,"Fair","Needs Improvement"))) | J6: =ROUND(100*(((1-MIN(1,COUNTIFS('Subject Reports'!A:A,$B6,'Subject Reports'!B:B,"Upper",'Subject Reports'!G:G,"Behind")/$N$2))+(1-MIN(1,COUNTIFS('Class Reports'!A:A,$B6,'Class Reports'!B:B,"Upper",'Class Reports'!G:G,"Poor")/$N$3))+(1-MIN(1,COUNTIFS('Class Reports'!A:A,$B6,'Class Reports'!B:B,"Upper",'Class Reports'!H:H,"Low")/$N$4))+(1-MIN(1,COUNTIFS('Staff Weekly'!A:A,$B6,'Staff Weekly'!B:B,"Upper",'Staff Weekly'!F:F,"No")/$N$5))+(1-MIN(1,COUNTIFS('Operations & Facilities'!A:A,$B6,'Operations & Facilities'!B:B,"Upper",'Operations & Facilities'!D:D,"Poor")/$N$6)))/5),0) | K6: =ROUND(100*(((1-MIN(1,COUNTIFS('Subject Reports'!A:A,$B6,'Subject Reports'!B:B,"Lower",'Subject Reports'!G:G,"Behind")/$N$2))+(1-MIN(1,COUNTIFS('Class Reports'!A:A,$B6,'Class Reports'!B:B,"Lower",'Class Reports'!G:G,"Poor")/$N$3))+(1-MIN(1,COUNTIFS('Class Reports'!A:A,$B6,'Class Reports'!B:B,"Lower",'Class Reports'!H:H,"Low")/$N$4))+(1-MIN(1,COUNTIFS('Staff Weekly'!A:A,$B6,'Staff Weekly'!B:B,"Lower",'Staff Weekly'!F:F,"No")/$N$5))+(1-MIN(1,COUNTIFS('Operations & Facilities'!A:A,$B6,'Operations & Facilities'!B:B,"Lower",'Operations & Facilities'!D:D,"Poor")/$N$6)))/5),0) | M6: Facility Poor | N6: 1
A7: Week 6 | C7: =COUNTIFS('Subject Reports'!A:A,$B7,'Subject Reports'!G:G,"Behind") | D7: =COUNTIFS('Class Reports'!A:A,$B7,'Class Reports'!G:G,"Poor") | E7: =COUNTIFS('Class Reports'!A:A,$B7,'Class Reports'!H:H,"Low") | F7: =COUNTIFS('Staff Weekly'!A:A,$B7,'Staff Weekly'!F:F,"No") | G7: =COUNTIFS('Operations & Facilities'!A:A,$B7,'Operations & Facilities'!D:D,"Poor") | H7: =ROUND(100*(((1-MIN(1,C7/$N$2))+(1-MIN(1,D7/$N$3))+(1-MIN(1,E7/$N$4))+(1-MIN(1,F7/$N$5))+(1-MIN(1,G7/$N$6)))/5),0) | I7: =IF(H7>=90,"Excellent",IF(H7>=75,"Good",IF(H7>=60,"Fair","Needs Improvement"))) | J7: =ROUND(100*(((1-MIN(1,COUNTIFS('Subject Reports'!A:A,$B7,'Subject Reports'!B:B,"Upper",'Subject Reports'!G:G,"Behind")/$N$2))+(1-MIN(1,COUNTIFS('Class Reports'!A:A,$B7,'Class Reports'!B:B,"Upper",'Class Reports'!G:G,"Poor")/$N$3))+(1-MIN(1,COUNTIFS('Class Reports'!A:A,$B7,'Class Reports'!B:B,"Upper",'Class Reports'!H:H,"Low")/$N$4))+(1-MIN(1,COUNTIFS('Staff Weekly'!A:A,$B7,'Staff Weekly'!B:B,"Upper",'Staff Weekly'!F:F,"No")/$N$5))+(1-MIN(1,COUNTIFS('Operations & Facilities'!A:A,$B7,'Operations & Facilities'!B:B,"Upper",'Operations & Facilities'!D:D,"Poor")/$N$6)))/5),0) | K7: =ROUND(100*(((1-MIN(1,COUNTIFS('Subject Reports'!A:A,$B7,'Subject Reports'!B:B,"Lower",'Subject Reports'!G:G,"Behind")/$N$2))+(1-MIN(1,COUNTIFS('Class Reports'!A:A,$B7,'Class Reports'!B:B,"Lower",'Class Reports'!G:G,"Poor")/$N$3))+(1-MIN(1,COUNTIFS('Class Reports'!A:A,$B7,'Class Reports'!B:B,"Lower",'Class Reports'!H:H,"Low")/$N$4))+(1-MIN(1,COUNTIFS('Staff Weekly'!A:A,$B7,'Staff Weekly'!B:B,"Lower",'Staff Weekly'!F:F,"No")/$N$5))+(1-MIN(1,COUNTIFS('Operations & Facilities'!A:A,$B7,'Operations & Facilities'!B:B,"Lower",'Operations & Facilities'!D:D,"Poor")/$N$6)))/5),0)
A8: Week 7 | C8: =COUNTIFS('Subject Reports'!A:A,$B8,'Subject Reports'!G:G,"Behind") | D8: =COUNTIFS('Class Reports'!A:A,$B8,'Class Reports'!G:G,"Poor") | E8: =COUNTIFS('Class Reports'!A:A,$B8,'Class Reports'!H:H,"Low") | F8: =COUNTIFS('Staff Weekly'!A:A,$B8,'Staff Weekly'!F:F,"No") | G8: =COUNTIFS('Operations & Facilities'!A:A,$B8,'Operations & Facilities'!D:D,"Poor") | H8: =ROUND(100*(((1-MIN(1,C8/$N$2))+(1-MIN(1,D8/$N$3))+(1-MIN(1,E8/$N$4))+(1-MIN(1,F8/$N$5))+(1-MIN(1,G8/$N$6)))/5),0) | I8: =IF(H8>=90,"Excellent",IF(H8>=75,"Good",IF(H8>=60,"Fair","Needs Improvement"))) | J8: =ROUND(100*(((1-MIN(1,COUNTIFS('Subject Reports'!A:A,$B8,'Subject Reports'!B:B,"Upper",'Subject Reports'!G:G,"Behind")/$N$2))+(1-MIN(1,COUNTIFS('Class Reports'!A:A,$B8,'Class Reports'!B:B,"Upper",'Class Reports'!G:G,"Poor")/$N$3))+(1-MIN(1,COUNTIFS('Class Reports'!A:A,$B8,'Class Reports'!B:B,"Upper",'Class Reports'!H:H,"Low")/$N$4))+(1-MIN(1,COUNTIFS('Staff Weekly'!A:A,$B8,'Staff Weekly'!B:B,"Upper",'Staff Weekly'!F:F,"No")/$N$5))+(1-MIN(1,COUNTIFS('Operations & Facilities'!A:A,$B8,'Operations & Facilities'!B:B,"Upper",'Operations & Facilities'!D:D,"Poor")/$N$6)))/5),0) | K8: =ROUND(100*(((1-MIN(1,COUNTIFS('Subject Reports'!A:A,$B8,'Subject Reports'!B:B,"Lower",'Subject Reports'!G:G,"Behind")/$N$2))+(1-MIN(1,COUNTIFS('Class Reports'!A:A,$B8,'Class Reports'!B:B,"Lower",'Class Reports'!G:G,"Poor")/$N$3))+(1-MIN(1,COUNTIFS('Class Reports'!A:A,$B8,'Class Reports'!B:B,"Lower",'Class Reports'!H:H,"Low")/$N$4))+(1-MIN(1,COUNTIFS('Staff Weekly'!A:A,$B8,'Staff Weekly'!B:B,"Lower",'Staff Weekly'!F:F,"No")/$N$5))+(1-MIN(1,COUNTIFS('Operations & Facilities'!A:A,$B8,'Operations & Facilities'!B:B,"Lower",'Operations & Facilities'!D:D,"Poor")/$N$6)))/5),0)
A9: Week 8 | C9: =COUNTIFS('Subject Reports'!A:A,$B9,'Subject Reports'!G:G,"Behind") | D9: =COUNTIFS('Class Reports'!A:A,$B9,'Class Reports'!G:G,"Poor") | E9: =COUNTIFS('Class Reports'!A:A,$B9,'Class Reports'!H:H,"Low") | F9: =COUNTIFS('Staff Weekly'!A:A,$B9,'Staff Weekly'!F:F,"No") | G9: =COUNTIFS('Operations & Facilities'!A:A,$B9,'Operations & Facilities'!D:D,"Poor") | H9: =ROUND(100*(((1-MIN(1,C9/$N$2))+(1-MIN(1,D9/$N$3))+(1-MIN(1,E9/$N$4))+(1-MIN(1,F9/$N$5))+(1-MIN(1,G9/$N$6)))/5),0) | I9: =IF(H9>=90,"Excellent",IF(H9>=75,"Good",IF(H9>=60,"Fair","Needs Improvement"))) | J9: =ROUND(100*(((1-MIN(1,COUNTIFS('Subject Reports'!A:A,$B9,'Subject Reports'!B:B,"Upper",'Subject Reports'!G:G,"Behind")/$N$2))+(1-MIN(1,COUNTIFS('Class Reports'!A:A,$B9,'Class Reports'!B:B,"Upper",'Class Reports'!G:G,"Poor")/$N$3))+(1-MIN(1,COUNTIFS('Class Reports'!A:A,$B9,'Class Reports'!B:B,"Upper",'Class Reports'!H:H,"Low")/$N$4))+(1-MIN(1,COUNTIFS('Staff Weekly'!A:A,$B9,'Staff Weekly'!B:B,"Upper",'Staff Weekly'!F:F,"No")/$N$5))+(1-MIN(1,COUNTIFS('Operations & Facilities'!A:A,$B9,'Operations & Facilities'!B:B,"Upper",'Operations & Facilities'!D:D,"Poor")/$N$6)))/5),0) | K9: =ROUND(100*(((1-MIN(1,COUNTIFS('Subject Reports'!A:A,$B9,'Subject Reports'!B:B,"Lower",'Subject Reports'!G:G,"Behind")/$N$2))+(1-MIN(1,COUNTIFS('Class Reports'!A:A,$B9,'Class Reports'!B:B,"Lower",'Class Reports'!G:G,"Poor")/$N$3))+(1-MIN(1,COUNTIFS('Class Reports'!A:A,$B9,'Class Reports'!B:B,"Lower",'Class Reports'!H:H,"Low")/$N$4))+(1-MIN(1,COUNTIFS('Staff Weekly'!A:A,$B9,'Staff Weekly'!B:B,"Lower",'Staff Weekly'!F:F,"No")/$N$5))+(1-MIN(1,COUNTIFS('Operations & Facilities'!A:A,$B9,'Operations & Facilities'!B:B,"Lower",'Operations & Facilities'!D:D,"Poor")/$N$6)))/5),0)
A10: Week 9 | C10: =COUNTIFS('Subject Reports'!A:A,$B10,'Subject Reports'!G:G,"Behind") | D10: =COUNTIFS('Class Reports'!A:A,$B10,'Class Reports'!G:G,"Poor") | E10: =COUNTIFS('Class Reports'!A:A,$B10,'Class Reports'!H:H,"Low") | F10: =COUNTIFS('Staff Weekly'!A:A,$B10,'Staff Weekly'!F:F,"No") | G10: =COUNTIFS('Operations & Facilities'!A:A,$B10,'Operations & Facilities'!D:D,"Poor") | H10: =ROUND(100*(((1-MIN(1,C10/$N$2))+(1-MIN(1,D10/$N$3))+(1-MIN(1,E10/$N$4))+(1-MIN(1,F10/$N$5))+(1-MIN(1,G10/$N$6)))/5),0) | I10: =IF(H10>=90,"Excellent",IF(H10>=75,"Good",IF(H10>=60,"Fair","Needs Improvement"))) | J10: =ROUND(100*(((1-MIN(1,COUNTIFS('Subject Reports'!A:A,$B10,'Subject Reports'!B:B,"Upper",'Subject Reports'!G:G,"Behind")/$N$2))+(1-MIN(1,COUNTIFS('Class Reports'!A:A,$B10,'Class Reports'!B:B,"Upper",'Class Reports'!G:G,"Poor")/$N$3))+(1-MIN(1,COUNTIFS('Class Reports'!A:A,$B10,'Class Reports'!B:B,"Upper",'Class Reports'!H:H,"Low")/$N$4))+(1-MIN(1,COUNTIFS('Staff Weekly'!A:A,$B10,'Staff Weekly'!B:B,"Upper",'Staff Weekly'!F:F,"No")/$N$5))+(1-MIN(1,COUNTIFS('Operations & Facilities'!A:A,$B10,'Operations & Facilities'!B:B,"Upper",'Operations & Facilities'!D:D,"Poor")/$N$6)))/5),0) | K10: =ROUND(100*(((1-MIN(1,COUNTIFS('Subject Reports'!A:A,$B10,'Subject Reports'!B:B,"Lower",'Subject Reports'!G:G,"Behind")/$N$2))+(1-MIN(1,COUNTIFS('Class Reports'!A:A,$B10,'Class Reports'!B:B,"Lower",'Class Reports'!G:G,"Poor")/$N$3))+(1-MIN(1,COUNTIFS('Class Reports'!A:A,$B10,'Class Reports'!B:B,"Lower",'Class Reports'!H:H,"Low")/$N$4))+(1-MIN(1,COUNTIFS('Staff Weekly'!A:A,$B10,'Staff Weekly'!B:B,"Lower",'Staff Weekly'!F:F,"No")/$N$5))+(1-MIN(1,COUNTIFS('Operations & Facilities'!A:A,$B10,'Operations & Facilities'!B:B,"Lower",'Operations & Facilities'!D:D,"Poor")/$N$6)))/5),0)
A11: Week 10 | C11: =COUNTIFS('Subject Reports'!A:A,$B11,'Subject Reports'!G:G,"Behind") | D11: =COUNTIFS('Class Reports'!A:A,$B11,'Class Reports'!G:G,"Poor") | E11: =COUNTIFS('Class Reports'!A:A,$B11,'Class Reports'!H:H,"Low") | F11: =COUNTIFS('Staff Weekly'!A:A,$B11,'Staff Weekly'!F:F,"No") | G11: =COUNTIFS('Operations & Facilities'!A:A,$B11,'Operations & Facilities'!D:D,"Poor") | H11: =ROUND(100*(((1-MIN(1,C11/$N$2))+(1-MIN(1,D11/$N$3))+(1-MIN(1,E11/$N$4))+(1-MIN(1,F11/$N$5))+(1-MIN(1,G11/$N$6)))/5),0) | I11: =IF(H11>=90,"Excellent",IF(H11>=75,"Good",IF(H11>=60,"Fair","Needs Improvement"))) | J11: =ROUND(100*(((1-MIN(1,COUNTIFS('Subject Reports'!A:A,$B11,'Subject Reports'!B:B,"Upper",'Subject Reports'!G:G,"Behind")/$N$2))+(1-MIN(1,COUNTIFS('Class Reports'!A:A,$B11,'Class Reports'!B:B,"Upper",'Class Reports'!G:G,"Poor")/$N$3))+(1-MIN(1,COUNTIFS('Class Reports'!A:A,$B11,'Class Reports'!B:B,"Upper",'Class Reports'!H:H,"Low")/$N$4))+(1-MIN(1,COUNTIFS('Staff Weekly'!A:A,$B11,'Staff Weekly'!B:B,"Upper",'Staff Weekly'!F:F,"No")/$N$5))+(1-MIN(1,COUNTIFS('Operations & Facilities'!A:A,$B11,'Operations & Facilities'!B:B,"Upper",'Operations & Facilities'!D:D,"Poor")/$N$6)))/5),0) | K11: =ROUND(100*(((1-MIN(1,COUNTIFS('Subject Reports'!A:A,$B11,'Subject Reports'!B:B,"Lower",'Subject Reports'!G:G,"Behind")/$N$2))+(1-MIN(1,COUNTIFS('Class Reports'!A:A,$B11,'Class Reports'!B:B,"Lower",'Class Reports'!G:G,"Poor")/$N$3))+(1-MIN(1,COUNTIFS('Class Reports'!A:A,$B11,'Class Reports'!B:B,"Lower",'Class Reports'!H:H,"Low")/$N$4))+(1-MIN(1,COUNTIFS('Staff Weekly'!A:A,$B11,'Staff Weekly'!B:B,"Lower",'Staff Weekly'!F:F,"No")/$N$5))+(1-MIN(1,COUNTIFS('Operations & Facilities'!A:A,$B11,'Operations & Facilities'!B:B,"Lower",'Operations & Facilities'!D:D,"Poor")/$N$6)))/5),0)
A12: Week 11 | C12: =COUNTIFS('Subject Reports'!A:A,$B12,'Subject Reports'!G:G,"Behind") | D12: =COUNTIFS('Class Reports'!A:A,$B12,'Class Reports'!G:G,"Poor") | E12: =COUNTIFS('Class Reports'!A:A,$B12,'Class Reports'!H:H,"Low") | F12: =COUNTIFS('Staff Weekly'!A:A,$B12,'Staff Weekly'!F:F,"No") | G12: =COUNTIFS('Operations & Facilities'!A:A,$B12,'Operations & Facilities'!D:D,"Poor") | H12: =ROUND(100*(((1-MIN(1,C12/$N$2))+(1-MIN(1,D12/$N$3))+(1-MIN(1,E12/$N$4))+(1-MIN(1,F12/$N$5))+(1-MIN(1,G12/$N$6)))/5),0) | I12: =IF(H12>=90,"Excellent",IF(H12>=75,"Good",IF(H12>=60,"Fair","Needs Improvement"))) | J12: =ROUND(100*(((1-MIN(1,COUNTIFS('Subject Reports'!A:A,$B12,'Subject Reports'!B:B,"Upper",'Subject Reports'!G:G,"Behind")/$N$2))+(1-MIN(1,COUNTIFS('Class Reports'!A:A,$B12,'Class Reports'!B:B,"Upper",'Class Reports'!G:G,"Poor")/$N$3))+(1-MIN(1,COUNTIFS('Class Reports'!A:A,$B12,'Class Reports'!B:B,"Upper",'Class Reports'!H:H,"Low")/$N$4))+(1-MIN(1,COUNTIFS('Staff Weekly'!A:A,$B12,'Staff Weekly'!B:B,"Upper",'Staff Weekly'!F:F,"No")/$N$5))+(1-MIN(1,COUNTIFS('Operations & Facilities'!A:A,$B12,'Operations & Facilities'!B:B,"Upper",'Operations & Facilities'!D:D,"Poor")/$N$6)))/5),0) | K12: =ROUND(100*(((1-MIN(1,COUNTIFS('Subject Reports'!A:A,$B12,'Subject Reports'!B:B,"Lower",'Subject Reports'!G:G,"Behind")/$N$2))+(1-MIN(1,COUNTIFS('Class Reports'!A:A,$B12,'Class Reports'!B:B,"Lower",'Class Reports'!G:G,"Poor")/$N$3))+(1-MIN(1,COUNTIFS('Class Reports'!A:A,$B12,'Class Reports'!B:B,"Lower",'Class Reports'!H:H,"Low")/$N$4))+(1-MIN(1,COUNTIFS('Staff Weekly'!A:A,$B12,'Staff Weekly'!B:B,"Lower",'Staff Weekly'!F:F,"No")/$N$5))+(1-MIN(1,COUNTIFS('Operations & Facilities'!A:A,$B12,'Operations & Facilities'!B:B,"Lower",'Operations & Facilities'!D:D,"Poor")/$N$6)))/5),0)
A13: Week 12 | C13: =COUNTIFS('Subject Reports'!A:A,$B13,'Subject Reports'!G:G,"Behind") | D13: =COUNTIFS('Class Reports'!A:A,$B13,'Class Reports'!G:G,"Poor") | E13: =COUNTIFS('Class Reports'!A:A,$B13,'Class Reports'!H:H,"Low") | F13: =COUNTIFS('Staff Weekly'!A:A,$B13,'Staff Weekly'!F:F,"No") | G13: =COUNTIFS('Operations & Facilities'!A:A,$B13,'Operations & Facilities'!D:D,"Poor") | H13: =ROUND(100*(((1-MIN(1,C13/$N$2))+(1-MIN(1,D13/$N$3))+(1-MIN(1,E13/$N$4))+(1-MIN(1,F13/$N$5))+(1-MIN(1,G13/$N$6)))/5),0) | I13: =IF(H13>=90,"Excellent",IF(H13>=75,"Good",IF(H13>=60,"Fair","Needs Improvement"))) | J13: =ROUND(100*(((1-MIN(1,COUNTIFS('Subject Reports'!A:A,$B13,'Subject Reports'!B:B,"Upper",'Subject Reports'!G:G,"Behind")/$N$2))+(1-MIN(1,COUNTIFS('Class Reports'!A:A,$B13,'Class Reports'!B:B,"Upper",'Class Reports'!G:G,"Poor")/$N$3))+(1-MIN(1,COUNTIFS('Class Reports'!A:A,$B13,'Class Reports'!B:B,"Upper",'Class Reports'!H:H,"Low")/$N$4))+(1-MIN(1,COUNTIFS('Staff Weekly'!A:A,$B13,'Staff Weekly'!B:B,"Upper",'Staff Weekly'!F:F,"No")/$N$5))+(1-MIN(1,COUNTIFS('Operations & Facilities'!A:A,$B13,'Operations & Facilities'!B:B,"Upper",'Operations & Facilities'!D:D,"Poor")/$N$6)))/5),0) | K13: =ROUND(100*(((1-MIN(1,COUNTIFS('Subject Reports'!A:A,$B13,'Subject Reports'!B:B,"Lower",'Subject Reports'!G:G,"Behind")/$N$2))+(1-MIN(1,COUNTIFS('Class Reports'!A:A,$B13,'Class Reports'!B:B,"Lower",'Class Reports'!G:G,"Poor")/$N$3))+(1-MIN(1,COUNTIFS('Class Reports'!A:A,$B13,'Class Reports'!B:B,"Lower",'Class Reports'!H:H,"Low")/$N$4))+(1-MIN(1,COUNTIFS('Staff Weekly'!A:A,$B13,'Staff Weekly'!B:B,"Lower",'Staff Weekly'!F:F,"No")/$N$5))+(1-MIN(1,COUNTIFS('Operations & Facilities'!A:A,$B13,'Operations & Facilities'!B:B,"Lower",'Operations & Facilities'!D:D,"Poor")/$N$6)))/5),0)
A14: Week 13 | C14: =COUNTIFS('Subject Reports'!A:A,$B14,'Subject Reports'!G:G,"Behind") | D14: =COUNTIFS('Class Reports'!A:A,$B14,'Class Reports'!G:G,"Poor") | E14: =COUNTIFS('Class Reports'!A:A,$B14,'Class Reports'!H:H,"Low") | F14: =COUNTIFS('Staff Weekly'!A:A,$B14,'Staff Weekly'!F:F,"No") | G14: =COUNTIFS('Operations & Facilities'!A:A,$B14,'Operations & Facilities'!D:D,"Poor") | H14: =ROUND(100*(((1-MIN(1,C14/$N$2))+(1-MIN(1,D14/$N$3))+(1-MIN(1,E14/$N$4))+(1-MIN(1,F14/$N$5))+(1-MIN(1,G14/$N$6)))/5),0) | I14: =IF(H14>=90,"Excellent",IF(H14>=75,"Good",IF(H14>=60,"Fair","Needs Improvement"))) | J14: =ROUND(100*(((1-MIN(1,COUNTIFS('Subject Reports'!A:A,$B14,'Subject Reports'!B:B,"Upper",'Subject Reports'!G:G,"Behind")/$N$2))+(1-MIN(1,COUNTIFS('Class Reports'!A:A,$B14,'Class Reports'!B:B,"Upper",'Class Reports'!G:G,"Poor")/$N$3))+(1-MIN(1,COUNTIFS('Class Reports'!A:A,$B14,'Class Reports'!B:B,"Upper",'Class Reports'!H:H,"Low")/$N$4))+(1-MIN(1,COUNTIFS('Staff Weekly'!A:A,$B14,'Staff Weekly'!B:B,"Upper",'Staff Weekly'!F:F,"No")/$N$5))+(1-MIN(1,COUNTIFS('Operations & Facilities'!A:A,$B14,'Operations & Facilities'!B:B,"Upper",'Operations & Facilities'!D:D,"Poor")/$N$6)))/5),0) | K14: =ROUND(100*(((1-MIN(1,COUNTIFS('Subject Reports'!A:A,$B14,'Subject Reports'!B:B,"Lower",'Subject Reports'!G:G,"Behind")/$N$2))+(1-MIN(1,COUNTIFS('Class Reports'!A:A,$B14,'Class Reports'!B:B,"Lower",'Class Reports'!G:G,"Poor")/$N$3))+(1-MIN(1,COUNTIFS('Class Reports'!A:A,$B14,'Class Reports'!B:B,"Lower",'Class Reports'!H:H,"Low")/$N$4))+(1-MIN(1,COUNTIFS('Staff Weekly'!A:A,$B14,'Staff Weekly'!B:B,"Lower",'Staff Weekly'!F:F,"No")/$N$5))+(1-MIN(1,COUNTIFS('Operations & Facilities'!A:A,$B14,'Operations & Facilities'!B:B,"Lower",'Operations & Facilities'!D:D,"Poor")/$N$6)))/5),0)
A15: Week 14 | C15: =COUNTIFS('Subject Reports'!A:A,$B15,'Subject Reports'!G:G,"Behind") | D15: =COUNTIFS('Class Reports'!A:A,$B15,'Class Reports'!G:G,"Poor") | E15: =COUNTIFS('Class Reports'!A:A,$B15,'Class Reports'!H:H,"Low") | F15: =COUNTIFS('Staff Weekly'!A:A,$B15,'Staff Weekly'!F:F,"No") | G15: =COUNTIFS('Operations & Facilities'!A:A,$B15,'Operations & Facilities'!D:D,"Poor") | H15: =ROUND(100*(((1-MIN(1,C15/$N$2))+(1-MIN(1,D15/$N$3))+(1-MIN(1,E15/$N$4))+(1-MIN(1,F15/$N$5))+(1-MIN(1,G15/$N$6)))/5),0) | I15: =IF(H15>=90,"Excellent",IF(H15>=75,"Good",IF(H15>=60,"Fair","Needs Improvement"))) | J15: =ROUND(100*(((1-MIN(1,COUNTIFS('Subject Reports'!A:A,$B15,'Subject Reports'!B:B,"Upper",'Subject Reports'!G:G,"Behind")/$N$2))+(1-MIN(1,COUNTIFS('Class Reports'!A:A,$B15,'Class Reports'!B:B,"Upper",'Class Reports'!G:G,"Poor")/$N$3))+(1-MIN(1,COUNTIFS('Class Reports'!A:A,$B15,'Class Reports'!B:B,"Upper",'Class Reports'!H:H,"Low")/$N$4))+(1-MIN(1,COUNTIFS('Staff Weekly'!A:A,$B15,'Staff Weekly'!B:B,"Upper",'Staff Weekly'!F:F,"No")/$N$5))+(1-MIN(1,COUNTIFS('Operations & Facilities'!A:A,$B15,'Operations & Facilities'!B:B,"Upper",'Operations & Facilities'!D:D,"Poor")/$N$6)))/5),0) | K15: =ROUND(100*(((1-MIN(1,COUNTIFS('Subject Reports'!A:A,$B15,'Subject Reports'!B:B,"Lower",'Subject Reports'!G:G,"Behind")/$N$2))+(1-MIN(1,COUNTIFS('Class Reports'!A:A,$B15,'Class Reports'!B:B,"Lower",'Class Reports'!G:G,"Poor")/$N$3))+(1-MIN(1,COUNTIFS('Class Reports'!A:A,$B15,'Class Reports'!B:B,"Lower",'Class Reports'!H:H,"Low")/$N$4))+(1-MIN(1,COUNTIFS('Staff Weekly'!A:A,$B15,'Staff Weekly'!B:B,"Lower",'Staff Weekly'!F:F,"No")/$N$5))+(1-MIN(1,COUNTIFS('Operations & Facilities'!A:A,$B15,'Operations & Facilities'!B:B,"Lower",'Operations & Facilities'!D:D,"Poor")/$N$6)))/5),0)

Sheet Term Performance Report
A1: ROYAL KINGS PREMIER SCHOOL
A2: TERM PERFORMANCE REPORT (WEEK 1 – WEEK 14)
A4: OVERALL PERFORMANCE SUMMARY
A5: Indicator | B5: Start (Week 1) | C5: End (Week 14) | D5: Trend
A6: Overall School Score % | B6: =INDEX('Term Summary'!H:H,2) | C6: =INDEX('Term Summary'!H:H,15) | D6: =IF(C6>B6,"⬆ Improving",IF(C6<B6,"⬇ Declining","➖ Stable"))
A7: Upper Campus Score % | B7: =INDEX('Term Summary'!J:J,2) | C7: =INDEX('Term Summary'!J:J,15) | D7: =IF(C7>B7,"⬆ Improving",IF(C7<B7,"⬇ Declining","➖ Stable"))
A8: Lower Campus Score % | B8: =INDEX('Term Summary'!K:K,2) | C8: =INDEX('Term Summary'!K:K,15) | D8: =IF(C8>B8,"⬆ Improving",IF(C8<B8,"⬇ Declining","➖ Stable"))
A10: ACADEMIC PERFORMANCE (KEY RISKS)
A11: Indicator | B11: Start (Week 1) | C11: End (Week 14) | D11: Trend
A12: Subjects Behind Syllabus (count) | B12: =INDEX('Term Summary'!C:C,2) | C12: =INDEX('Term Summary'!C:C,15) | D12: =IF(C12<B12,"⬆ Improving",IF(C12>B12,"⬇ Worsening","➖ Stable"))
A13: Low Homework Classes (count) | B13: =INDEX('Term Summary'!E:E,2) | C13: =INDEX('Term Summary'!E:E,15) | D13: =IF(C13<B13,"⬆ Improving",IF(C13>B13,"⬇ Worsening","➖ Stable"))
A15: DISCIPLINE & STUDENT WELFARE (KEY RISKS)
A16: Indicator | B16: Start (Week 1) | C16: End (Week 14) | D16: Trend
A17: Poor Discipline Classes (count) | B17: =INDEX('Term Summary'!D:D,2) | C17: =INDEX('Term Summary'!D:D,15) | D17: =IF(C17<B17,"⬆ Improving",IF(C17>B17,"⬇ Worsening","➖ Stable"))
A19: TEACHER PERFORMANCE (KEY RISKS)
A20: Indicator | B20: Start (Week 1) | C20: End (Week 14) | D20: Trend
A21: Teachers Not Marking (count) | B21: =INDEX('Term Summary'!F:F,2) | C21: =INDEX('Term Summary'!F:F,15) | D21: =IF(C21<B21,"⬆ Improving",IF(C21>B21,"⬇ Worsening","➖ Stable"))
A23: FACILITIES & OPERATIONS (KEY RISKS)
A24: Indicator | B24: Start (Week 1) | C24: End (Week 14) | D24: Trend
A25: Facility Areas Poor (count) | B25: =INDEX('Term Summary'!G:G,2) | C25: =INDEX('Term Summary'!G:G,15) | D25: =IF(C25<B25,"⬆ Improving",IF(C25>B25,"⬇ Worsening","➖ Stable"))

Sheet Term Snapshot
A1: ROYAL KINGS PREMIER SCHOOL
A2: TERM PERFORMANCE SNAPSHOT (ONE PAGE)
A4: Metric | B4: Start (Week 1) | C4: End (Week 14) | D4: Trend
A5: Overall Score % | B5: =INDEX('Term Summary'!H:H,2) | C5: =INDEX('Term Summary'!H:H,15) | D5: =IF(C5>B5,"⬆ Improving",IF(C5<B5,"⬇ Declining","➖ Stable"))
A6: Upper Campus Score % | B6: =INDEX('Term Summary'!J:J,2) | C6: =INDEX('Term Summary'!J:J,15) | D6: =IF(C6>B6,"⬆ Improving",IF(C6<B6,"⬇ Declining","➖ Stable"))
A7: Lower Campus Score % | B7: =INDEX('Term Summary'!K:K,2) | C7: =INDEX('Term Summary'!K:K,15) | D7: =IF(C7>B7,"⬆ Improving",IF(C7<B7,"⬇ Declining","➖ Stable"))
A8: Subjects Behind (count) | B8: =INDEX('Term Summary'!C:C,2) | C8: =INDEX('Term Summary'!C:C,15) | D8: =IF(C8<B8,"⬆ Improving",IF(C8>B8,"⬇ Worsening","➖ Stable"))
A9: Poor Discipline (count) | B9: =INDEX('Term Summary'!D:D,2) | C9: =INDEX('Term Summary'!D:D,15) | D9: =IF(C9<B9,"⬆ Improving",IF(C9>B9,"⬇ Worsening","➖ Stable"))
A10: Low Homework (count) | B10: =INDEX('Term Summary'!E:E,2) | C10: =INDEX('Term Summary'!E:E,15) | D10: =IF(C10<B10,"⬆ Improving",IF(C10>B10,"⬇ Worsening","➖ Stable"))
A11: Not Marking (count) | B11: =INDEX('Term Summary'!F:F,2) | C11: =INDEX('Term Summary'!F:F,15) | D11: =IF(C11<B11,"⬆ Improving",IF(C11>B11,"⬇ Worsening","➖ Stable"))
A12: Facility Poor (count) | B12: =INDEX('Term Summary'!G:G,2) | C12: =INDEX('Term Summary'!G:G,15) | D12: =IF(C12<B12,"⬆ Improving",IF(C12>B12,"⬇ Worsening","➖ Stable"))
A14: Summary Comment:

Sheet Teacher Rankings
A1: Week Ending | B1: Teacher Name | C1: Campus (Upper/Lower) | D1: Marking Score (20) | E1: Schemes Score (20) | F1: Punctuality Score (20) | G1: Class Management Score (20) | H1: Syllabus Progress Score (20) | I1: Total Score (100) | J1: Rank | K1: Performance Level | L1: Notes / Action
D2: =IF(COUNTIFS('Staff Weekly'!A:A,$A2,'Staff Weekly'!C:C,$B2,'Staff Weekly'!F:F,"Yes")>0,20,0) | E2: =IF(COUNTIFS('Staff Weekly'!A:A,$A2,'Staff Weekly'!C:C,$B2,'Staff Weekly'!G:G,"Yes")>0,20,0) | F2: =IF(COUNTIFS('Staff Weekly'!A:A,$A2,'Staff Weekly'!C:C,$B2,'Staff Weekly'!D:D,"Yes")>0,20,0) | G2: =IF($B2="","",IF(COUNTIFS('Class Reports'!A:A,$A2,'Class Reports'!D:D,$B2,'Class Reports'!G:G,"Poor") + COUNTIFS('Class Reports'!A:A,$A2,'Class Reports'!D:D,$B2,'Class Reports'!H:H,"Low")=0,20,10)) | H2: =IF($B2="","",IF(COUNTIFS('Subject Reports'!A:A,$A2,'Subject Reports'!D:D,$B2,'Subject Reports'!G:G,"Behind")=0,20,10)) | I2: =IF($B2="","",SUM(D2:H2)) | J2: =IF($I2="","",RANK($I2,$I$2:$I$200,0)) | K2: =IF($I2="","",IF($I2>=90,"Outstanding",IF($I2>=75,"Very Good",IF($I2>=60,"Good","Needs Support"))))
D3: =IF(COUNTIFS('Staff Weekly'!A:A,$A3,'Staff Weekly'!C:C,$B3,'Staff Weekly'!F:F,"Yes")>0,20,0) | E3: =IF(COUNTIFS('Staff Weekly'!A:A,$A3,'Staff Weekly'!C:C,$B3,'Staff Weekly'!G:G,"Yes")>0,20,0) | F3: =IF(COUNTIFS('Staff Weekly'!A:A,$A3,'Staff Weekly'!C:C,$B3,'Staff Weekly'!D:D,"Yes")>0,20,0) | G3: =IF($B3="","",IF(COUNTIFS('Class Reports'!A:A,$A3,'Class Reports'!D:D,$B3,'Class Reports'!G:G,"Poor") + COUNTIFS('Class Reports'!A:A,$A3,'Class Reports'!D:D,$B3,'Class Reports'!H:H,"Low")=0,20,10)) | H3: =IF($B3="","",IF(COUNTIFS('Subject Reports'!A:A,$A3,'Subject Reports'!D:D,$B3,'Subject Reports'!G:G,"Behind")=0,20,10)) | I3: =IF($B3="","",SUM(D3:H3)) | J3: =IF($I3="","",RANK($I3,$I$2:$I$200,0)) | K3: =IF($I3="","",IF($I3>=90,"Outstanding",IF($I3>=75,"Very Good",IF($I3>=60,"Good","Needs Support"))))
D4: =IF(COUNTIFS('Staff Weekly'!A:A,$A4,'Staff Weekly'!C:C,$B4,'Staff Weekly'!F:F,"Yes")>0,20,0) | E4: =IF(COUNTIFS('Staff Weekly'!A:A,$A4,'Staff Weekly'!C:C,$B4,'Staff Weekly'!G:G,"Yes")>0,20,0) | F4: =IF(COUNTIFS('Staff Weekly'!A:A,$A4,'Staff Weekly'!C:C,$B4,'Staff Weekly'!D:D,"Yes")>0,20,0) | G4: =IF($B4="","",IF(COUNTIFS('Class Reports'!A:A,$A4,'Class Reports'!D:D,$B4,'Class Reports'!G:G,"Poor") + COUNTIFS('Class Reports'!A:A,$A4,'Class Reports'!D:D,$B4,'Class Reports'!H:H,"Low")=0,20,10)) | H4: =IF($B4="","",IF(COUNTIFS('Subject Reports'!A:A,$A4,'Subject Reports'!D:D,$B4,'Subject Reports'!G:G,"Behind")=0,20,10)) | I4: =IF($B4="","",SUM(D4:H4)) | J4: =IF($I4="","",RANK($I4,$I$2:$I$200,0)) | K4: =IF($I4="","",IF($I4>=90,"Outstanding",IF($I4>=75,"Very Good",IF($I4>=60,"Good","Needs Support"))))
D5: =IF(COUNTIFS('Staff Weekly'!A:A,$A5,'Staff Weekly'!C:C,$B5,'Staff Weekly'!F:F,"Yes")>0,20,0) | E5: =IF(COUNTIFS('Staff Weekly'!A:A,$A5,'Staff Weekly'!C:C,$B5,'Staff Weekly'!G:G,"Yes")>0,20,0) | F5: =IF(COUNTIFS('Staff Weekly'!A:A,$A5,'Staff Weekly'!C:C,$B5,'Staff Weekly'!D:D,"Yes")>0,20,0) | G5: =IF($B5="","",IF(COUNTIFS('Class Reports'!A:A,$A5,'Class Reports'!D:D,$B5,'Class Reports'!G:G,"Poor") + COUNTIFS('Class Reports'!A:A,$A5,'Class Reports'!D:D,$B5,'Class Reports'!H:H,"Low")=0,20,10)) | H5: =IF($B5="","",IF(COUNTIFS('Subject Reports'!A:A,$A5,'Subject Reports'!D:D,$B5,'Subject Reports'!G:G,"Behind")=0,20,10)) | I5: =IF($B5="","",SUM(D5:H5)) | J5: =IF($I5="","",RANK($I5,$I$2:$I$200,0)) | K5: =IF($I5="","",IF($I5>=90,"Outstanding",IF($I5>=75,"Very Good",IF($I5>=60,"Good","Needs Support"))))
